{"date":"Thu Oct 26 2023 12:38:45 GMT+0700 (Western Indonesia Time)","error":{"code":"ERR_UNHANDLED_REJECTION"},"exception":true,"level":"error","message":"uncaughtException: This error originated either by throwing inside of an async function without a catch block, or by rejecting a promise which was not handled with .catch(). The promise rejected with the reason \"ups rejection\".\nUnhandledPromiseRejection: This error originated either by throwing inside of an async function without a catch block, or by rejecting a promise which was not handled with .catch(). The promise rejected with the reason \"ups rejection\".","os":{"loadavg":[2.9697265625,2.78955078125,2.86962890625],"uptime":673397},"process":{"argv":["/usr/local/bin/node","/Users/mubarok/Programming/Nodejs/logging/test/handle-rejection.test.js"],"cwd":"/Users/mubarok/Programming/Nodejs/logging","execPath":"/usr/local/bin/node","gid":20,"memoryUsage":{"arrayBuffers":73154,"external":801846,"heapTotal":10420224,"heapUsed":6588824,"rss":45531136},"pid":68597,"uid":501,"version":"v16.13.1"},"stack":"UnhandledPromiseRejection: This error originated either by throwing inside of an async function without a catch block, or by rejecting a promise which was not handled with .catch(). The promise rejected with the reason \"ups rejection\".","trace":[]}
